---
title: "C++ Nested Exceptions"
description: "Learn how to handle nested exceptions in C++ - understanding how exceptions can be thrown from within catch blocks and best practices for managing complex exception scenarios."

---

# C++ Nested Exceptions

## Introduction

When working with complex C++ applications, error handling becomes increasingly important. Sometimes, errors can occur while you're already handling another error - this is where **nested exceptions** come into play. Nested exceptions occur when an exception is thrown while another exception is being processed, typically inside a catch block.

In this tutorial, you'll learn:
- What nested exceptions are and why they occur
- How to handle exceptions within catch blocks
- How C++11's `std::nested_exception` works
- Best practices for managing nested exception scenarios

## Understanding Nested Exceptions

### The Basic Concept

A nested exception happens when you're in the middle of handling one exception, and another exception gets thrown. This can happen when your error recovery code itself has a problem.

Consider this simple scenario:

```cpp
#include <iostream>
#include <fstream>
#include <string>

void processFile(const std::string& filename) {
    try {
        std::ifstream file(filename);
        if (!file.is_open()) {
            throw std::runtime_error("Failed to open file");
        }
        
        // Process file contents...
    }
    catch (const std::runtime_error& e) {
        std::cout << "Error: " << e.what() << std::endl;
        
        // Attempt recovery by creating the file
        std::ofstream newFile(filename);
        if (!newFile.is_open()) {
            // A second exception while handling the first!
            throw std::runtime_error("Failed to create recovery file");
        }
    }
}

int main() {
    try {
        processFile("nonexistent_file.txt");
    }
    catch (const std::exception& e) {
        std::cout << "Recovery failed: " << e.what() << std::endl;
    }
    
    return 0;
}
```

**Output (if recovery fails):**
```
Error: Failed to open file
Recovery failed: Failed to create recovery file
```

In this example, we have a nested exception scenario because a second exception could be thrown from within the catch block that's handling the first exception.

## Handling Nested Exceptions in C++

### Before C++11: Basic Approaches

Before C++11, there was no standard mechanism for handling nested exceptions. Programmers typically used one of these approaches:

1. **Catch and handle within the catch block:**

```cpp
try {
    // risky operation 1
}
catch (const std::exception& e) {
    try {
        // risky recovery operation
    }
    catch (const std::exception& nested_e) {
        // Handle the nested exception
        std::cerr << "Original error: " << e.what() << std::endl;
        std::cerr << "During recovery: " << nested_e.what() << std::endl;
    }
}
```

2. **Using custom error classes to combine error information:**

```cpp
class RecoveryError : public std::exception {
private:
    std::string message;
    
public:
    RecoveryError(const std::exception& original, const std::string& recovery_msg) {
        message = std::string("Original error: ") + original.what() + 
                  "\nRecovery error: " + recovery_msg;
    }
    
    const char* what() const noexcept override {
        return message.c_str();
    }
};

// Usage
try {
    // risky operation
}
catch (const std::exception& e) {
    try {
        // recovery that might fail
    }
    catch (...) {
        throw RecoveryError(e, "Recovery failed");
    }
}
```

### C++11 and Beyond: `std::nested_exception`

C++11 introduced a more standardized approach with `std::nested_exception`. This class is designed to capture and store an exception that was active when a new exception was thrown.

The key features of `std::nested_exception` are:

1. **`std::rethrow_if_nested()`**: Used to rethrow the nested exception if it exists
2. **`std::throw_with_nested()`**: Throws an exception while preserving the current exception

Let's see how it works:

```cpp
#include <iostream>
#include <exception>
#include <stdexcept>

void processData() {
    throw std::runtime_error("Data processing error");
}

void backupData() {
    try {
        processData();
    }
    catch (const std::exception& e) {
        std::throw_with_nested(std::runtime_error("Backup failed"));
    }
}

int main() {
    try {
        backupData();
    }
    catch (const std::exception& e) {
        std::cerr << "Error: " << e.what() << std::endl;
        
        try {
            std::rethrow_if_nested(e);
        }
        catch (const std::exception& nested) {
            std::cerr << "Caused by: " << nested.what() << std::endl;
        }
    }
    
    return 0;
}
```

**Output:**
```
Error: Backup failed
Caused by: Data processing error
```

### How `std::throw_with_nested` Works

The `std::throw_with_nested` function is a key part of nested exception handling. Here's what happens:

1. It takes an exception object as an argument
2. It creates a new exception that publicly inherits from both:
   - The type of the thrown exception
   - The `std::nested_exception` class
3. It stores the current exception as the nested exception
4. It throws the new compound exception object

## Handling Multiple Levels of Nested Exceptions

In complex applications, you might encounter multiple levels of nested exceptions. Here's a more complete example showing how to unwind and display all exception levels:

```cpp
#include <iostream>
#include <exception>
#include <stdexcept>
#include <string>

// Function to recursively print exception details
void print_exception(const std::exception& e, int level = 0) {
    std::cerr << std::string(level, ' ') << "Exception: " << e.what() << std::endl;
    try {
        std::rethrow_if_nested(e);
    } 
    catch(const std::exception& nested) {
        print_exception(nested, level + 2);
    }
    catch(...) {
        std::cerr << std::string(level + 2, ' ') << "Unknown exception" << std::endl;
    }
}

// Functions with different levels of exceptions
void level3() {
    throw std::runtime_error("Level 3 error");
}

void level2() {
    try {
        level3();
    } 
    catch(...) {
        std::throw_with_nested(std::runtime_error("Level 2 error"));
    }
}

void level1() {
    try {
        level2();
    } 
    catch(...) {
        std::throw_with_nested(std::runtime_error("Level 1 error"));
    }
}

int main() {
    try {
        level1();
    } 
    catch(const std::exception& e) {
        std::cerr << "Exception stack:" << std::endl;
        print_exception(e);
    }
    
    return 0;
}
```

**Output:**
```
Exception stack:
Exception: Level 1 error
  Exception: Level 2 error
    Exception: Level 3 error
```

The `print_exception` function recursively unpacks each level of nested exceptions, displaying them in a readable hierarchical format.

## Real-World Applications

### Database Transaction with Error Logging

Here's a real-world example demonstrating how nested exceptions can be useful in a database operation with proper error logging:

```cpp
#include <iostream>
#include <exception>
#include <stdexcept>
#include <string>
#include <memory>

// Mock database classes for illustration
class DatabaseConnection {
public:
    void connect(const std::string& connString) {
        if (connString.empty()) {
            throw std::runtime_error("Empty connection string");
        }
        // Successfully connected
    }
    
    void executeQuery(const std::string& query) {
        if (query.empty()) {
            throw std::runtime_error("Empty query");
        }
        // Query executed
    }
    
    void commit() {
        // Commit successful
    }
    
    void rollback() {
        // For demonstration, let's say rollback sometimes fails
        throw std::runtime_error("Rollback failed - connection lost");
    }
};

class Logger {
public:
    void logError(const std::exception& e) {
        std::cerr << "LOGGED ERROR: " << e.what() << std::endl;
        try {
            std::rethrow_if_nested(e);
        }
        catch(const std::exception& nested) {
            std::cerr << "NESTED ERROR: " << nested.what() << std::endl;
        }
    }
};

// Our application code
void performDatabaseOperation() {
    auto db = std::make_unique<DatabaseConnection>();
    auto logger = std::make_unique<Logger>();
    
    try {
        db->connect("db_server:3306");
        
        try {
            db->executeQuery(""); // This will throw an exception
            db->commit();
        }
        catch(const std::exception& e) {
            try {
                db->rollback(); // This could also throw an exception
            }
            catch(...) {
                std::throw_with_nested(std::runtime_error("Transaction failed and couldn't rollback"));
            }
            std::throw_with_nested(std::runtime_error("Transaction failed"));
        }
    }
    catch(const std::exception& e) {
        logger->logError(e);
        throw; // Re-throw the exception to be handled by the caller
    }
}

int main() {
    try {
        performDatabaseOperation();
    }
    catch(const std::exception& e) {
        std::cerr << "Operation failed: " << e.what() << std::endl;
    }
    
    return 0;
}
```

**Output:**
```
LOGGED ERROR: Transaction failed
NESTED ERROR: Transaction failed and couldn't rollback
Operation failed: Transaction failed
```

In this example:
1. We attempt a database operation
2. The operation fails with an empty query
3. During rollback, another exception occurs
4. We use nested exceptions to maintain the full chain of errors
5. Our logger prints the complete error hierarchy
6. The main application receives and handles the top-level exception

## Best Practices for Nested Exceptions

When working with nested exceptions, follow these best practices:

1. **Use standard exception handling patterns**:
   - Always use `std::throw_with_nested` when throwing from a catch block
   - Always check for nested exceptions with `std::rethrow_if_nested`

2. **Create meaningful exception hierarchies**:
   - Include contextual information at each level
   - Make each exception message clear about what went wrong at that specific level

3. **Avoid excessively deep nesting**:
   - If you find many levels of nested exceptions, reconsider your error handling strategy
   - Consider using a more structured approach like error codes or result objects for predictable failures

4. **Properly unwind all exceptions**:
   - Always implement a recursive exception printing function like the one shown above
   - Log all levels of exceptions, not just the top one

5. **Consider exception safety guarantees**:
   - Strong guarantee: Operations either complete fully or have no effect
   - Basic guarantee: Class invariants are preserved, no resources leak
   - No-throw guarantee: Operations never throw exceptions

## Summary

Nested exceptions in C++ provide a powerful mechanism for maintaining the complete chain of errors in complex applications. With C++11's `std::nested_exception`, `std::throw_with_nested`, and `std::rethrow_if_nested`, you can create robust error handling that captures and communicates the full context of errors.

Key points to remember:
- Nested exceptions occur when an exception is thrown while handling another exception
- C++11 introduced standardized mechanisms for handling nested exceptions
- Use `std::throw_with_nested` to preserve the current exception when throwing a new one
- Use `std::rethrow_if_nested` to check for and handle nested exceptions
- Create recursive printing functions to display the full exception hierarchy
- Follow best practices to maintain clear and manageable exception handling

## Additional Resources

- [C++ Reference: std::nested_exception](https://en.cppreference.com/w/cpp/error/nested_exception)
- [C++ Reference: std::throw_with_nested](https://en.cppreference.com/w/cpp/error/throw_with_nested)
- [C++ Reference: std::rethrow_if_nested](https://en.cppreference.com/w/cpp/error/rethrow_if_nested)

## Exercises

1. Write a program that simulates a file processing system where:
   - Opening a non-existent file throws an exception
   - The recovery mechanism tries to create the file but might fail due to permissions
   - Implement proper nested exception handling to report both issues

2. Extend the database example to include multiple levels of operations (connect, query, process results) and handle potential exceptions at each level while maintaining the complete error chain.

3. Create a custom exception class hierarchy for a specific domain (e.g., network operations) that properly works with nested exceptions and provides detailed error reporting.