---
title: "C# Finally Block"
description: "Learn how to use the finally block in C# exception handling to ensure critical code always executes, regardless of exceptions."

---

# C# Finally Block

## Introduction

When working with operations that require cleanup (like file operations, database connections, or network resources), you need a way to ensure these resources are properly released, even if an exception occurs. The `finally` block in C# provides this guarantee by executing code regardless of whether an exception was thrown or caught in a corresponding `try` block.

In this tutorial, you'll learn:

- What the `finally` block is and why it's important
- How to use the `finally` block with `try` and `catch`
- Best practices for writing cleanup code
- Real-world examples of `finally` in action

## Understanding the Finally Block

### Basic Structure

The `finally` block is part of C#'s exception handling mechanism, which typically looks like this:

```csharp
try
{
    // Code that might throw an exception
}
catch (Exception ex)
{
    // Code to handle the exception
}
finally
{
    // Code that will always run, whether an exception occurred or not
}
```

The `finally` block will execute in all scenarios except:
- If the program exits unexpectedly (like a power failure)
- If an infinite loop occurs in the `try` or `catch` blocks
- If `Environment.Exit()` is called
- If the process is terminated

## How the Finally Block Works

Let's look at a simple example to see the `finally` block in action:

```csharp
using System;

class Program
{
    static void Main()
    {
        Console.WriteLine("Starting program...");
        
        try
        {
            Console.WriteLine("Inside try block");
            int result = 10 / 0; // This will throw a DivideByZeroException
            Console.WriteLine("This line won't execute"); // This never runs
        }
        catch (DivideByZeroException ex)
        {
            Console.WriteLine($"Caught an exception: {ex.Message}");
        }
        finally
        {
            Console.WriteLine("Finally block executed");
        }
        
        Console.WriteLine("Program continues...");
    }
}
```

Output:
```
Starting program...
Inside try block
Caught an exception: Attempted to divide by zero.
Finally block executed
Program continues...
```

Notice how the `finally` block executes even though an exception occurred. If we changed our code to remove the exception, the output would be:

```
Starting program...
Inside try block
Finally block executed
Program continues...
```

The `finally` block executes in both cases!

## Using Finally Without Catch

You can also use `finally` without a `catch` block:

```csharp
try
{
    // Code that might throw an exception
}
finally
{
    // Cleanup code
}
```

In this case, if an exception occurs, the `finally` block will execute and then the exception will propagate up the call stack to be handled elsewhere.

## When to Use the Finally Block

The `finally` block is ideal for:

1. **Resource cleanup**: Closing files, connections, or releasing resources
2. **Restoring state**: Returning objects to a known good state
3. **Logging**: Recording that operations have completed (successful or not)

### Resource Cleanup Example

This example demonstrates proper file handling using the `finally` block:

```csharp
using System;
using System.IO;

class Program
{
    static void Main()
    {
        FileStream file = null;
        
        try
        {
            file = new FileStream("data.txt", FileMode.Open);
            // Read from the file...
            byte[] buffer = new byte[1024];
            file.Read(buffer, 0, buffer.Length);
            
            // Process the file contents...
            Console.WriteLine("File processed successfully");
        }
        catch (FileNotFoundException)
        {
            Console.WriteLine("Error: The file was not found.");
        }
        catch (IOException ex)
        {
            Console.WriteLine($"Error reading the file: {ex.Message}");
        }
        finally
        {
            // Close the file even if an exception occurred
            if (file != null)
            {
                file.Close();
                Console.WriteLine("File closed in finally block");
            }
        }
    }
}
```

If the file exists and can be processed, you'll see:
```
File processed successfully
File closed in finally block
```

If the file doesn't exist:
```
Error: The file was not found.
```

The `finally` block is crucial here because it ensures the file is closed regardless of whether the operation completed successfully or not.

## Modern Resource Management in C#

While `finally` blocks are important to understand, modern C# provides even better ways to handle resource cleanup through the `using` statement, which implicitly creates a `try/finally` block:

```csharp
using System;
using System.IO;

class Program
{
    static void Main()
    {
        try
        {
            // This automatically creates a finally block that calls Dispose()
            using (FileStream file = new FileStream("data.txt", FileMode.Open))
            {
                // Use the file...
                byte[] buffer = new byte[1024];
                file.Read(buffer, 0, buffer.Length);
                Console.WriteLine("File processed successfully");
            } // The file is automatically closed here
        }
        catch (FileNotFoundException)
        {
            Console.WriteLine("Error: The file was not found.");
        }
        catch (IOException ex)
        {
            Console.WriteLine($"Error reading the file: {ex.Message}");
        }
    }
}
```

Behind the scenes, the `using` statement generates a `try/finally` block that ensures the `Dispose()` method is called on the resource when execution leaves the scope.

## Real-World Applications

### Database Connection Example

Here's how you might use a `finally` block to ensure a database connection is closed properly:

```csharp
using System;
using System.Data.SqlClient;

class DatabaseOperations
{
    public void ReadCustomerData(int customerId)
    {
        SqlConnection connection = null;
        SqlCommand command = null;
        SqlDataReader reader = null;
        
        try
        {
            string connectionString = "Server=myServerAddress;Database=myDataBase;User Id=myUsername;Password=myPassword;";
            connection = new SqlConnection(connectionString);
            connection.Open();
            
            command = new SqlCommand("SELECT * FROM Customers WHERE CustomerId = @CustomerId", connection);
            command.Parameters.AddWithValue("@CustomerId", customerId);
            
            reader = command.ExecuteReader();
            
            if (reader.Read())
            {
                string name = reader["Name"].ToString();
                Console.WriteLine($"Customer found: {name}");
            }
            else
            {
                Console.WriteLine("No customer found with that ID");
            }
        }
        catch (SqlException ex)
        {
            Console.WriteLine($"Database error occurred: {ex.Message}");
        }
        catch (Exception ex)
        {
            Console.WriteLine($"An error occurred: {ex.Message}");
        }
        finally
        {
            // Close all resources in reverse order
            reader?.Close();
            command?.Dispose();
            connection?.Close();
            Console.WriteLine("Database resources have been cleaned up");
        }
    }
}
```

### Thread Synchronization Example

Another common use case is ensuring thread locks are released:

```csharp
using System;
using System.Threading;

class ThreadExample
{
    private static readonly object lockObject = new object();
    private static int counter = 0;
    
    public static void IncrementCounter()
    {
        // Attempt to take the lock
        Monitor.Enter(lockObject);
        
        try
        {
            // Critical section - only one thread can execute this at a time
            counter++;
            Console.WriteLine($"Counter value: {counter}, Thread ID: {Thread.CurrentThread.ManagedThreadId}");
            
            // Simulate some work
            Thread.Sleep(100);
        }
        finally
        {
            // Always release the lock even if an exception occurs
            Monitor.Exit(lockObject);
            Console.WriteLine($"Lock released by Thread ID: {Thread.CurrentThread.ManagedThreadId}");
        }
    }
}
```

## Execution Flow and Control

The `finally` block can change program flow in some important ways:

### Return Statements and Finally

A `return` statement in a `try` or `catch` block does not prevent the `finally` block from executing:

```csharp
using System;

class Program
{
    static int DivideNumbers(int a, int b)
    {
        try
        {
            Console.WriteLine("Attempting division");
            
            if (b == 0)
            {
                Console.WriteLine("Cannot divide by zero");
                return -1; // Early return
            }
            
            return a / b; // Normal return
        }
        finally
        {
            Console.WriteLine("Finally block executed");
        }
    }
    
    static void Main()
    {
        int result1 = DivideNumbers(10, 2);
        Console.WriteLine($"Result 1: {result1}");
        
        int result2 = DivideNumbers(10, 0);
        Console.WriteLine($"Result 2: {result2}");
    }
}
```

Output:
```
Attempting division
Finally block executed
Result 1: 5
Attempting division
Cannot divide by zero
Finally block executed
Result 2: -1
```

Notice how the `finally` block always executes before the function returns.

### Nested Try-Finally Blocks

You can nest `try/finally` blocks to handle multiple resources:

```csharp
using System;
using System.IO;

class Program
{
    static void ProcessFiles()
    {
        FileStream file1 = null;
        FileStream file2 = null;
        
        try
        {
            file1 = new FileStream("file1.txt", FileMode.Open);
            
            try
            {
                file2 = new FileStream("file2.txt", FileMode.Open);
                
                // Process both files...
                Console.WriteLine("Processing both files");
            }
            finally
            {
                // Close file2 if it was opened
                if (file2 != null)
                {
                    file2.Close();
                    Console.WriteLine("file2 closed");
                }
            }
        }
        finally
        {
            // Close file1 if it was opened
            if (file1 != null)
            {
                file1.Close();
                Console.WriteLine("file1 closed");
            }
        }
    }
}
```

## Best Practices

1. **Keep finally blocks short and focused**: Include only essential cleanup code.
2. **Avoid throwing exceptions in finally blocks**: Doing so can mask the original exception.
3. **Consider the using statement**: For IDisposable objects, prefer the `using` statement when possible.
4. **Check for null**: Before closing resources, check that they were actually opened.
5. **Multiple resources**: Close resources in the reverse order they were opened.

## Common Pitfalls

### Adding More Complexity Than Needed

Sometimes developers place too much complex logic in `finally` blocks. Keep your `finally` blocks focused on cleanup only.

### Throwing Exceptions in Finally Blocks

This is a bad practice because it replaces the original exception:

```csharp
try
{
    // This throws an important exception
    throw new ArgumentException("Original exception");
}
finally
{
    // This exception replaces the original exception!
    throw new InvalidOperationException("New exception");
} 
// The caller will only see "New exception"
```

Instead, handle potential exceptions within the `finally` block:

```csharp
try
{
    // Original operation
    throw new ArgumentException("Original exception");
}
finally
{
    try
    {
        // Cleanup code that might throw an exception
        SomeCleanupOperation();
    }
    catch (Exception ex)
    {
        // Log the cleanup exception but don't throw it
        Console.WriteLine($"Cleanup failed: {ex.Message}");
    }
}
```

## Summary

The `finally` block is a powerful feature in C#'s exception handling system that ensures critical cleanup code runs regardless of whether an exception occurs. Key points to remember:

- The `finally` block always executes (except in rare circumstances like sudden application termination)
- It's perfect for resource cleanup operations like closing files and connections
- It executes even when `return`, `break`, or `continue` statements are used in `try` or `catch` blocks
- For `IDisposable` objects, the `using` statement provides a cleaner alternative
- Keep `finally` blocks simple and focused on cleanup

By mastering the `finally` block, you'll write more robust code that properly manages resources even in the face of unexpected errors.

## Exercises

1. **Basic Practice**: Write a program that opens a text file, reads its contents, and ensures the file is properly closed using a `finally` block.

2. **Database Exercise**: Create a method that connects to a database, executes a query, and ensures all database resources are closed properly.

3. **Challenge**: Implement a custom resource manager class with a `Lock()` and `Unlock()` method, and use it in a program with proper exception handling.

## Additional Resources

- [C# Documentation on Exception Handling](https://docs.microsoft.com/en-us/dotnet/csharp/programming-guide/exceptions/)
- [C# using Statement](https://docs.microsoft.com/en-us/dotnet/csharp/language-reference/keywords/using-statement)
- [Implementing IDisposable Pattern](https://docs.microsoft.com/en-us/dotnet/standard/garbage-collection/implementing-dispose)